<div class="c13 lst-kix_list_2-2 start" start="1"><h2 style="text-align:center;"><span class="c1">Errors &amp; Exceptions</span></h2></div><p class="c8 c20"><span class="c7 c15"></span></p><p class="c8"><span class="c30">As of now we have seen so many examples from them we encounter two different types of errors .They are : Syntax error and Exceptions.</span></p><p class="c8 c20"><span class="c28 c7"></span></p><h4 class="c8"><span class="c28 c7"><strong>Syntax Error </strong></span></h4><p class="c8"><span class="c3">Syntax errors are the most common complaints you get while you are learning Python:</span></p><strong>Example :</strong><p class="c8"><span class="c9 c7">&nbsp; &nbsp; &nbsp; &nbsp; &nbsp;&gt;&gt;for i in range(1,5) </span></p><p class="c8"><span class="c9 c7">&nbsp; &nbsp; &nbsp; &nbsp; &nbsp; &nbsp; &nbsp; &nbsp; &nbsp;&nbsp; print i</span></p><strong>Output :</strong><p class="c8"><span class="c9 c7">&nbsp; File &quot;&lt;stdin&gt;&quot;, line 1</span></p><p class="c8"><span class="c9 c7">&nbsp; &nbsp; for i in range(1,5)</span></p><p class="c8"><span class="c9 c7">&nbsp; &nbsp; &nbsp; &nbsp; &nbsp; &nbsp; &nbsp; &nbsp; &nbsp; &nbsp; &nbsp; &nbsp;^</span></p><p class="c8"><span class="c9 c7">SyntaxError: invalid syntax</span></p><p class="c8"><span class="c3">The error is caused by the token preceding</span><span class="c30 c36">&nbsp;</span><span class="c3">the arrow: in the example, the error is detected at the keyword print , since a colon &nbsp;: &nbsp;is missing before it.</span></p><p class="c8 c20"><span class="c3 c7"></span></p><h4><strong>Exceptions&nbsp;&nbsp;Handling&nbsp;:</strong></h4><p class="c8"><span class="c3">Errors detected during execution are called exceptions and are not unconditionally fatal</span><span class="c35">.</span><span class="c3">&nbsp;It implies that the problem doesn&#39;t occur frequently, i.e. the exception is the &quot;exception to the rule&quot;.</span></p><p class="c8"><span class="c3">Exception handling is a construct to handle or deal the error automatically. As Python and some other programming languages have bulit-in support for exception handling.</span></p><p class="c8 c20"><span class="c33 c7"></span></p>

<h4 class="c8"><span class="c23"><strong>Bulit-in Exceptions :</strong></span></h4><a id="t.6f2a1f608eb901c09bfbecb15390b4e7bd26c840"></a><a id="t.0"></a><table class="c41"><tbody><tr class="c5"><td class="c6" colspan="1" rowspan="1"><p class="c1"><span class="c30 c40">Base Exception </span></p></td><td class="c11" colspan="1" rowspan="1"><p class="c0"><span class="c9 c7">Base class for all exceptions.</span></p></td></tr><tr class="c5"><td class="c6" colspan="1" rowspan="1"><p class="c1"><span class="c3">Exception</span></p></td><td class="c11" colspan="1" rowspan="1"><p class="c0"><span class="c3 c7">All user-defined exceptions should also be derived from this class.</span></p></td></tr><tr class="c5"><td class="c6" colspan="1" rowspan="1"><p class="c1"><span class="c3">StandardError</span></p></td><td class="c11" colspan="1" rowspan="1"><p class="c0"><span class="c7 c9">Itself is derived from exception.</span></p></td></tr><tr class="c5"><td class="c6" colspan="1" rowspan="1"><p class="c1"><span class="c3">ArithmeticError</span></p></td><td class="c11" colspan="1" rowspan="1"><p class="c0"><span class="c3 c7">Base class for those built-in exceptions that are raised for various arithmetic error.</span></p></td></tr><tr class="c5"><td class="c6" colspan="1" rowspan="1"><p class="c1"><span class="c3">BufferError</span></p></td><td class="c11" colspan="1" rowspan="1"><p class="c0"><span class="c9 c7">Occur </span><span class="c3 c7">when a buffer related operation cannot be performed.</span></p></td></tr><tr class="c5"><td class="c6" colspan="1" rowspan="1"><p class="c1"><span class="c3">LookupError</span></p></td><td class="c11" colspan="1" rowspan="1"><p class="c0"><span class="c3">Occur when a key or index used on a mapping or sequence is invalid.</span></p></td></tr><tr class="c5"><td class="c6" colspan="1" rowspan="1"><p class="c1"><span class="c3">EnvironmentError</span></p></td><td class="c11" colspan="1" rowspan="1"><p class="c0"><span class="c9 c7">Occurs outside the python system.</span></p></td></tr><tr class="c5"><td class="c6" colspan="1" rowspan="1"><p class="c1"><span class="c3">AssertionError</span></p></td><td class="c11" colspan="1" rowspan="1"><p class="c0"><span class="c9 c7">Occurs when an assert statement fails</span></p></td></tr><tr class="c5"><td class="c6" colspan="1" rowspan="1"><p class="c1"><span class="c3">AttributeError</span></p></td><td class="c11" colspan="1" rowspan="1"><p class="c0"><span class="c9 c7">Occurs when an attribute reference (or) assignment fails</span></p></td></tr><tr class="c5"><td class="c6" colspan="1" rowspan="1"><p class="c1"><span class="c3">EOFError</span></p></td><td class="c11" colspan="1" rowspan="1"><p class="c0"><span class="c9 c7">Occurs when built-in function hits an end-of-file condition.</span></p></td></tr><tr class="c5"><td class="c6" colspan="1" rowspan="1"><p class="c1"><span class="c3">FloatingPointError</span></p></td><td class="c11" colspan="1" rowspan="1"><p class="c0"><span class="c9 c7">Occurs when floating point operation fails.</span></p></td></tr><tr class="c5"><td class="c6" colspan="1" rowspan="1"><p class="c1"><span class="c3">GeneratorExit</span></p></td><td class="c11" colspan="1" rowspan="1"><p class="c0"><span class="c9 c7">Occurs when close() method is called.</span></p></td></tr><tr class="c5"><td class="c6" colspan="1" rowspan="1"><p class="c1"><span class="c3">IOError</span></p></td><td class="c11" colspan="1" rowspan="1"><p class="c0"><span class="c9 c7">Occurs when I/O operation fails for I/O related reasons. </span></p></td></tr><tr class="c5"><td class="c6" colspan="1" rowspan="1"><p class="c1"><span class="c3">ImportError</span></p></td><td class="c11" colspan="1" rowspan="1"><p class="c0"><span class="c9 c7">Occurs when import statement fails to find the module definitions.</span></p></td></tr><tr class="c5"><td class="c6" colspan="1" rowspan="1"><p class="c1"><span class="c3">IndexError</span></p></td><td class="c11" colspan="1" rowspan="1"><p class="c0"><span class="c9 c7">Occurs when a sequence subscript is out of range.</span></p></td></tr><tr class="c5"><td class="c6" colspan="1" rowspan="1"><p class="c1"><span class="c3">KeyError</span></p></td><td class="c11" colspan="1" rowspan="1"><p class="c0"><span class="c9 c7">Occurs when a mapping key is not found &nbsp;in the set of existing keys.</span></p></td></tr><tr class="c5"><td class="c6" colspan="1" rowspan="1"><p class="c1"><span class="c3">KeyboardInterrupt</span></p></td><td class="c11" colspan="1" rowspan="1"><p class="c0"><span class="c9 c7">Occurs when the user hits the interrupt key.(control-c,delete-d)</span></p></td></tr><tr class="c5"><td class="c6" colspan="1" rowspan="1"><p class="c1"><span class="c3">MemoryError</span></p></td><td class="c11" colspan="1" rowspan="1"><p class="c0"><span class="c9 c7">Occurs when the operation runs out of the memory.</span></p></td></tr><tr class="c5"><td class="c6" colspan="1" rowspan="1"><p class="c1"><span class="c3">NameError</span></p></td><td class="c11" colspan="1" rowspan="1"><p class="c0"><span class="c9 c7">Occurs when global (or) local name is not found.</span></p></td></tr><tr class="c5"><td class="c6" colspan="1" rowspan="1"><p class="c1"><span class="c3">NotImplementedError</span></p></td><td class="c11" colspan="1" rowspan="1"><p class="c0"><span class="c9 c7">Occurs when required derived classes to override the method.</span></p></td></tr><tr class="c5"><td class="c6" colspan="1" rowspan="1"><p class="c1"><span class="c3">OSError</span></p></td><td class="c11" colspan="1" rowspan="1"><p class="c0"><span class="c9 c7">Occurs when a function returns a system-related error.</span></p></td></tr><tr class="c5"><td class="c6" colspan="1" rowspan="1"><p class="c1"><span class="c3">OverflowError</span></p></td><td class="c11" colspan="1" rowspan="1"><p class="c0"><span class="c3 c7">Occurs when the result of an arithmetic operation is too large to be represented.</span></p></td></tr><tr class="c5"><td class="c6" colspan="1" rowspan="1"><p class="c1"><span class="c3">RuntimeError</span></p></td><td class="c11" colspan="1" rowspan="1"><p class="c0"><span class="c3 c7">Occurs when an error is detected that doesn&rsquo;t come to any of the other categories.</span></p></td></tr><tr class="c5"><td class="c6" colspan="1" rowspan="1"><p class="c1"><span class="c3">StopIteration</span></p></td><td class="c11" colspan="1" rowspan="1"><p class="c0"><span class="c9 c7">Occurs when there is no further values of iterators next() method.</span></p></td></tr><tr class="c5"><td class="c6" colspan="1" rowspan="1"><p class="c1"><span class="c3">IndentationError</span></p></td><td class="c11" colspan="1" rowspan="1"><p class="c0"><span class="c9 c7">Occurs when there is incorrect indentation.</span></p></td></tr><tr class="c5"><td class="c6" colspan="1" rowspan="1"><p class="c1"><span class="c3">TabError</span></p></td><td class="c11" colspan="1" rowspan="1"><p class="c0"><span class="c3 c7">Occurs when indentation contains an inconsistent use of tabs and spaces.</span></p></td></tr><tr class="c5"><td class="c6" colspan="1" rowspan="1"><p class="c1"><span class="c3">SystemError</span></p></td><td class="c11" colspan="1" rowspan="1"><p class="c0"><span class="c9 c7">Occurs when the interpreter finds internal error.</span></p></td></tr><tr class="c5"><td class="c6" colspan="1" rowspan="1"><p class="c1"><span class="c3">SystemExit</span></p></td><td class="c11" colspan="1" rowspan="1"><p class="c0"><span class="c7 c26">Raised by the sys.exit() function</span></p></td></tr><tr class="c5"><td class="c6" colspan="1" rowspan="1"><p class="c1"><span class="c3">TypeError</span></p></td><td class="c11" colspan="1" rowspan="1"><p class="c0"><span class="c3 c7">Occurs when an operation or function is applied to an object of inappropriate type.</span></p></td></tr><tr class="c5"><td class="c6" colspan="1" rowspan="1"><p class="c1"><span class="c3">UnboundLocalError</span></p></td><td class="c11" colspan="1" rowspan="1"><p class="c0"><span class="c3 c7">Occurs when trying to access a local variable in a function or method but no value has been assigned to it</span></p></td></tr><tr class="c5"><td class="c6" colspan="1" rowspan="1"><p class="c1"><span class="c3">UnicodeError</span></p></td><td class="c11" colspan="1" rowspan="1"><p class="c0"><span class="c3 c7">Occurs when a Unicode-related encoding or decoding error.</span></p></td></tr><tr class="c5"><td class="c6" colspan="1" rowspan="1"><p class="c1"><span class="c3">UnicodeEncodeError</span></p></td><td class="c11" colspan="1" rowspan="1"><p class="c0"><span class="c3 c7">Occurs when a Unicode-related error during encoding. </span></p></td></tr><tr class="c5"><td class="c6" colspan="1" rowspan="1"><p class="c1"><span class="c3">UnicodeDecodeError</span></p></td><td class="c11" colspan="1" rowspan="1"><p class="c0"><span class="c3 c7">Occurs when a Unicode-related error during decoding.</span></p></td></tr><tr class="c5"><td class="c6" colspan="1" rowspan="1"><p class="c1"><span class="c3">UnicodeTranslateError</span></p></td><td class="c11" colspan="1" rowspan="1"><p class="c0"><span class="c3 c7">Occurs when a Unicode-related error during translating.</span></p></td></tr><tr class="c5"><td class="c6" colspan="1" rowspan="1"><p class="c1"><span class="c3">ValueError</span></p></td><td class="c11" colspan="1" rowspan="1"><p class="c0"><span class="c9 c7">Occurs when an operation or function receives inappropriate value. &nbsp;</span></p></td></tr><tr class="c5"><td class="c6" colspan="1" rowspan="1"><p class="c1"><span class="c3">VMSError</span></p></td><td class="c11" colspan="1" rowspan="1"><p class="c0"><span class="c9 c7">Occurs when VMS specific errors</span></p></td></tr><tr class="c5"><td class="c6" colspan="1" rowspan="1"><p class="c1"><span class="c3">WindowsError</span></p></td><td class="c11" colspan="1" rowspan="1"><p class="c0"><span class="c9 c7">Raised when window specific errors occur. </span></p></td></tr><tr class="c5"><td class="c6" colspan="1" rowspan="1"><p class="c1"><span class="c3">ZeroDivisionError</span></p></td><td class="c11" colspan="1" rowspan="1"><p class="c0"><span class="c3 c7">Occurs when the second argument of a division or modulo operation is zero.</span></p></td></tr></tbody></table><p class="c1 c20"><span class="c3 c7"></span></p><h4 class="c1"><span class="c23"><strong>Catching Exceptions </strong></span></h4><p class="c1"><span class="c3">In python, try statement is used to handle exceptions. The operation which can be raise exception is placed in try clause and the code that handle the exception is written in except clause.</span></p><h4><strong>Example :</strong></h4><p class="c1"><span class="c3">while True:</span></p><p class="c1"><span class="c3">&nbsp; &nbsp; &nbsp; &nbsp; try:</span></p><p class="c1"><span class="c3">&nbsp;&nbsp;&nbsp;&nbsp;&nbsp;&nbsp;&nbsp;&nbsp;&nbsp; n=input(&ldquo;enter a number:&rdquo;)</span></p><p class="c1"><span class="c3">&nbsp; &nbsp; &nbsp; &nbsp; &nbsp; &nbsp; n=int(n)</span></p><p class="c1"><span class="c3">&nbsp;&nbsp;&nbsp;&nbsp;&nbsp;&nbsp;&nbsp;&nbsp;&nbsp; break</span></p><p class="c1"><span class="c3">&nbsp; &nbsp; &nbsp; &nbsp;except:</span></p><p class="c1"><span class="c3">&nbsp; &nbsp; &nbsp; &nbsp; &nbsp; &nbsp; &nbsp; print &ldquo;not a valid number&rdquo;</span></p><p class="c1"><span class="c3">print &ldquo;entered successfully&rdquo;</span></p><strong>Output :</strong><p class="c1"><span class="c3">enter a number : 7</span></p><p class="c1"><span class="c3">entered successfully</span></p><h4 class="c1"><span class="c21"><strong>Example :</strong></span></h4><p class="c1"><span class="c3">def catch(msg):</span></p><p class="c1"><span class="c3">&nbsp; &nbsp; try:</span></p><p class="c1"><span class="c3">&nbsp; &nbsp; &nbsp; &nbsp; raise ValueError(msg)</span></p><p class="c1"><span class="c3">&nbsp; &nbsp; except ValueError as e:</span></p><p class="c1"><span class="c3">&nbsp; &nbsp; &nbsp; &nbsp; if str(e)!=&quot;hello&quot;:</span></p><p class="c1"><span class="c3">&nbsp; &nbsp; &nbsp; &nbsp; &nbsp; &nbsp; raise</span></p><p class="c1"><span class="c3">&nbsp; &nbsp; &nbsp; &nbsp; else:</span></p><p class="c1"><span class="c3">&nbsp; &nbsp; &nbsp; &nbsp; &nbsp; &nbsp; print &quot;caught!&quot;</span></p><p class="c1"><span class="c3">catch(&quot;hello&quot;)</span></p><strong>Output :</strong><p class="c1"><span class="c3">caught!</span></p><p class="c1"><span class="c3">- Here,</span><span class="c3 c22">in except ValueError, e, e is an instance of the exception, not a string. So when you test if e is not equal to a particular string, that test is always False. Try:if str(e)!=&quot;hello&quot; instead.</span></p><p class="c1 c20"><span class="c32 c7"></span></p><h4 class="c1"><span class="c23"><strong>Catching Specific Exceptions </strong></span></h4><p class="c1"><span class="c3">A try clause can have any number of except clause to handle them differently but only one will be executed in case an exception occurs.</span></p><p class="c1"><span class="c3">To specify multiple exceptions in an except clause,We can use a tuple of values.</span></p><strong>Example :</strong><p class="c1"><span class="c3 c7">try:</span></p><p class="c1"><span class="c3 c7">&nbsp; &nbsp; &nbsp; age=input(&lsquo;enter your age:&rdquo;)</span></p><p class="c1"><span class="c3 c7">except ValueError:</span></p><p class="c1"><span class="c3 c7">&nbsp; &nbsp; &nbsp; &nbsp;print &lsquo;invalid value&rsquo;</span></p><p class="c1"><span class="c3 c7">except keyboardInterrupt:</span></p><p class="c1"><span class="c3 c7">&nbsp; &nbsp; &nbsp; &nbsp; print &lsquo;you interrupted the keys&rsquo;</span></p><p class="c1"><span class="c3 c7">else:</span></p><p class="c1"><span class="c3 c7">&nbsp; &nbsp; &nbsp; &nbsp; if age&gt;50:</span></p><p class="c1"><span class="c3 c7">&nbsp;&nbsp;&nbsp;&nbsp;&nbsp;&nbsp;&nbsp;&nbsp;&nbsp; print &lsquo;you are old&rsquo;</span></p><p class="c1"><span class="c3 c7">&nbsp; &nbsp; &nbsp; &nbsp; else:</span></p><p class="c1"><span class="c3 c7">&nbsp;&nbsp;&nbsp;&nbsp;&nbsp;&nbsp;&nbsp;&nbsp;&nbsp; print &lsquo;you are &nbsp;young&rsquo;</span></p><strong>Output :</strong><div ><p class="c1"><span class="c3">enter your age: 51</span></p><p class="c1"><span class="c3">you are old</span></p><p class="c1"><span class="c3">enter your age: 24</span></p><p class="c1"><span class="c3">you are young</span></p><p class="c1"><span class="c3">enter your age: a</span></p><p class="c1"><span class="c3">invalid value</span></p><p class="c1"><span class="c3">enter your age: cntrl+c</span></p><p class="c1"><span class="c3 c7">you interrupted the keys</span></p></div><h4 class="c1"><span class="c23 c7"><strong>Raising Exceptions</strong></span></h4><p class="c1"><span class="c3 c7 c22">The raise</span><span class="c21 c7 c22">&nbsp;</span><span class="c3 c7 c22">statement allows the programmer to occur a specified exception.</span></p><p class="c1"><span class="c3 c7 c22">The </span><span class="c3 c7">raise</span><span class="c3 c7 c22">&nbsp;indicates the exception to be raised. This must be either an exception instance or an exception class</span></p><strong>Syntax :</strong><p class="c1"><span class="c3 c7">&nbsp; &nbsp; &nbsp; &nbsp; &nbsp; &nbsp; raise [Exception [, args [, traceback]]]</span></p><strong>Example :</strong><p class="c1"><span class="c3 c7">try:</span></p><p class="c1"><span class="c3 c7">&nbsp; &nbsp; &nbsp; a=input(&ldquo;enter a number : &rdquo;)</span></p><p class="c1"><span class="c3 c7">&nbsp; &nbsp; &nbsp; if a&gt;=0:</span></p><p class="c1"><span class="c3 c7">&nbsp;&nbsp;&nbsp;&nbsp;&nbsp;&nbsp;&nbsp;&nbsp;raise ValueError(&ldquo;Negative number&rdquo;)</span></p><p class="c1"><span class="c3 c7">except ValueError as ve:</span></p><p class="c1"><span class="c3 c7">&nbsp; &nbsp; &nbsp; print ve</span></p><strong>Output :</strong><p class="c1"><span class="c3 c7">enter a number : -12</span></p><p class="c1"><span class="c3 c7">&nbsp;Negative number</span></p> 
<h4 class="c1"><span class="c23 c7"><strong>try&hellip;..finally</strong></span></h4><p class="c1"><span class="c3 c7">The finally clause is optional. It is intended to define clean-up actions that must be executed under all cases. A finally clause is always executed before leaving the try statement, whether an exception has occurred or not.</span></p><strong>Syntax :</strong><p class="c1"><span class="c3 c7">try:</span></p><p class="c1"><span class="c3 c7">&nbsp; &nbsp; &nbsp; do operations here</span></p><p class="c1"><span class="c21 c7">&nbsp; &nbsp; &nbsp; &hellip;&hellip;&hellip;&hellip;&hellip;&hellip;&hellip;..</span></p><p class="c1"><span class="c21 c7">&nbsp; </span><span class="c3 c7"># if there is any exception this will be skipped</span></p><p class="c1"><span class="c3 c7">finally:</span></p><p class="c1"><span class="c3 c7">&nbsp; &nbsp; &nbsp;This will be executed</span></p><strong>Example :</strong><p class="c1"><span class="c3 c7">try:</span></p><p class="c1"><span class="c3 c7">&nbsp; &nbsp; &nbsp;x=input(&nbsp;&nbsp;&nbsp;&nbsp;&nbsp;&nbsp;&nbsp;&nbsp;&ldquo;enter a number :&rdquo;)</span></p><p class="c1"><span class="c3 c7">&nbsp; &nbsp; &nbsp;result=4*x</span></p><p class="c1"><span class="c3 c7">except KeyboardInterrupt:</span></p><p class="c1"><span class="c3 c7">&nbsp; &nbsp; &nbsp;print &ldquo;interruption&rdquo;</span></p><p class="c1"><span class="c3 c7">else:</span></p><p class="c1"><span class="c3 c7">&nbsp; &nbsp; &nbsp;print result</span></p><p class="c1"><span class="c3 c7">finally:</span></p><p class="c1"><span class="c3 c7">&nbsp; &nbsp; &nbsp;print &ldquo;finally&rdquo;</span></p><strong>Output :</strong><p class="c1"><span class="c3">enter a number : 5</span></p><p class="c1"><span class="c3">20</span></p><p class="c1"><span class="c3">finally</span></p><h4 class="c1"><span class="c23">User-defined Exceptions</span></h4><p class="c1"><span class="c3">A user can create his own errors by creating a new exception class. Exceptions need to be derived from the exception class, either directly or indirectly.</span></p><strong>Example :</strong><p class="c1"><span class="c3">class Sunny(Exception):</span></p><p class="c1"><span class="c3">&nbsp;&nbsp;&nbsp;&nbsp;&nbsp;&nbsp;&nbsp;&nbsp;def __init__(self, value):&nbsp;&nbsp;&nbsp;&nbsp;&nbsp;&nbsp;&nbsp;&nbsp;&nbsp;&nbsp;&nbsp;&nbsp;&nbsp;&nbsp;&nbsp;&nbsp;&nbsp;&nbsp;&nbsp;&nbsp;&nbsp;&nbsp;&nbsp;&nbsp;&nbsp;&nbsp;&nbsp;&nbsp;&nbsp;&nbsp;&nbsp;&nbsp;#__init__ Constructor or Initializer</span></p><p class="c1"><span class="c3">&nbsp;&nbsp;&nbsp;&nbsp;&nbsp;&nbsp;&nbsp;&nbsp;&nbsp;&nbsp;&nbsp;&nbsp;&nbsp;&nbsp;&nbsp;&nbsp;self.value = value</span></p><p class="c1"><span class="c3">&nbsp;&nbsp;&nbsp;&nbsp;&nbsp;&nbsp;&nbsp;&nbsp;def __str__(self):&nbsp;&nbsp;&nbsp;&nbsp;&nbsp;&nbsp;&nbsp;&nbsp;&nbsp;&nbsp;&nbsp;&nbsp;&nbsp;&nbsp;&nbsp;&nbsp;&nbsp;&nbsp;&nbsp;&nbsp;&nbsp;&nbsp;&nbsp;&nbsp;&nbsp;&nbsp;&nbsp;&nbsp;&nbsp;&nbsp;&nbsp;&nbsp;&nbsp;&nbsp;&nbsp;&nbsp;&nbsp;&nbsp;&nbsp;&nbsp;# __str__ is to print() the value</span></p><p class="c1"><span class="c3">&nbsp;&nbsp;&nbsp;&nbsp;&nbsp;&nbsp;&nbsp;&nbsp;&nbsp;&nbsp;&nbsp;&nbsp;&nbsp;&nbsp;&nbsp;&nbsp;return(self.value)</span></p><p class="c1"><span class="c3">try:</span></p><p class="c1"><span class="c3">&nbsp;&nbsp;&nbsp;&nbsp;&nbsp;&nbsp;&nbsp;&nbsp;raise(Sunny(10/5))</span></p><p class="c1"><span class="c3">except Sunny as s:&nbsp;&nbsp;&nbsp;&nbsp;&nbsp;&nbsp;&nbsp;&nbsp;&nbsp;&nbsp;&nbsp;&nbsp;&nbsp;&nbsp;&nbsp;&nbsp;&nbsp;&nbsp;&nbsp;&nbsp;&nbsp;&nbsp;&nbsp;&nbsp;&nbsp;&nbsp;&nbsp;&nbsp;&nbsp;&nbsp;&nbsp;&nbsp;&nbsp;&nbsp;&nbsp;&nbsp;&nbsp;&nbsp;&nbsp;&nbsp;&nbsp;&nbsp;&nbsp;&nbsp;&nbsp;&nbsp;&nbsp;&nbsp;# Value of Exception is stored in s</span></p><p class="c1"><span class="c3">&nbsp;&nbsp;&nbsp;&nbsp;&nbsp;&nbsp;&nbsp;&nbsp;print &#39;A new exception occurred : &#39;, s.value</span></p><strong>Output :</strong><p class="c1"><span class="c3">&nbsp;&nbsp;&nbsp;&nbsp;&nbsp;&nbsp;&nbsp;&nbsp;A new exception occurred : 2</span></p><p class="c1 c20"><span class="c3 c7"></span></p><p class="c1"><span class="c3">- we have created a user-defined exception called Sunny. which is derived from the Exception class. This new exception can be raised, using the raise statement and that value is stored in s ,when you get into exception then stored value is printed.</span></p><h4 class="c1"><span class="c28 c7">Errors Derived From Super Class Exception</span></h4><p class="c1"><span class="c13 c7">Super class exceptions are used when module need to handle different types of errors. This can be done by creating a base class for exceptions defined by that module.</span></p><h4 class="c1"><span class="c16 c7">Example :</span></h4><p class="c1"><span class="c13 c7">class MyException(Exception):</span></p><p class="c1"><span class="c13 c7">&nbsp; &nbsp; pass</span></p><p class="c1"><span class="c13 c7">class ValidationError(MyException):</span></p><p class="c1"><span class="c13 c7">&nbsp; &nbsp; def __init__(self, message, errors):</span></p><p class="c1"><span class="c13 c7">&nbsp; &nbsp; &nbsp; &nbsp; self.message=message</span></p><p class="c1"><span class="c13 c7">&nbsp; &nbsp; &nbsp; &nbsp; self.errors=errors</span></p><p class="c1"><span class="c13 c7">try:</span></p><p class="c1"><span class="c13 c7">&nbsp; &nbsp; raise MyException({&quot;message&quot;:&quot;hiiii&quot;,&quot;fruits&quot;:[&quot;apple&quot;,&rdquo;grapes&rdquo;,&rdquo;banana&rdquo;]})</span></p><p class="c1"><span class="c13 c7">except MyException as e:</span></p><p class="c1"><span class="c13 c7">&nbsp; &nbsp; details=e.args[0]</span></p><p class="c1"><span class="c13 c7">&nbsp; &nbsp; print details[&quot;fruits&quot;]</span></p><strong>Output :</strong><p class="c1"><span class="c13 c7">[&lsquo;apple&rsquo;,&rsquo;grapes&rsquo;,&rsquo;banana&rsquo;]</span></p><p class="c1 c20"><span class="c13 c7"></span></p><h4 class="c1"><span class="c28 c7"><strong>Using standard exceptions as base class</strong></span></h4><p class="c1"><span class="c3">Here,Runtime error is a class is a standard exception which is raised when a generated error does not fall into any category.</span></p><h4 class="c1"><span class="c16 c7">Example :</span></h4><p class="c1"><span class="c13 c7">class ValidationError(RuntimeError):</span></p><p class="c1"><span class="c13 c7">&nbsp; &nbsp; def __init__(self,arg):</span></p><p class="c1"><span class="c13 c7">&nbsp; &nbsp; &nbsp; &nbsp; self.args=arg</span></p><p class="c1"><span class="c13 c7">try:</span></p><p class="c1"><span class="c13 c7">&nbsp; &nbsp; raise ValidationError(&quot;hello&quot;)</span></p><p class="c1"><span class="c13 c7">except ValidationError as e:</span></p><p class="c1"><span class="c13 c7">&nbsp; &nbsp; print e.args</span></p><strong>Output :</strong><p class="c1"><span class="c13 c7">(&#39;h&#39;, &#39;e&#39;, &#39;l&#39;, &#39;l&#39;, &#39;o&#39;)</span></p><p class="c1"><span class="c30">-</span><span class="c3">The above example illustrate, how to use runtime error as base class and Validation error as derived class. </span></p><p class="c1 c20"><span class="c7 c40 c42"></span></p><p class="c1 c20"><span class="c7 c12"></span></p>